time: 2017-07-04 15:13:16.314656Z
tags: worker-0
test: setUpClass (tests.ScenarioNoError)
time: 2017-07-04 15:13:16.314656Z
failure: setUpClass (tests.ScenarioNoError) [ multipart
Content-Type: text/x-traceback;charset=utf8,language=python
traceback
440
Traceback (most recent call last):
  File "/root/workspace/cloudbase-init-ci/argus/scenarios/base.py", line 144, in setUpClass
    cls.prepare_instance()
  File "/root/workspace/cloudbase-init-ci/argus/scenarios/base.py", line 162, in prepare_instance
    cls.prepare_recipe()
  File "/root/workspace/cloudbase-init-ci/argus/scenarios/cloud/base.py", line 31, in prepare_recipe
    return cls.recipe.prepare(service_type=cls.service_type)
  File "/root/workspace/cloudbase-init-ci/argus/recipes/cloud/base.py", line 197, in prepare
    self.wait_cbinit_finalization()
  File "/root/workspace/cloudbase-init-ci/argus/recipes/cloud/windows.py", line 266, in wait_cbinit_finalization
    searched_paths=paths)
  File "/root/workspace/cloudbase-init-ci/argus/action_manager/windows.py", line 338, in check_cbinit_service
    command_type=util.POWERSHELL)
  File "/root/workspace/cloudbase-init-ci/argus/client/windows.py", line 331, in run_command_until_condition
    .format(cmd))
argus.exceptions.ArgusTimeoutError: Command 'Test-Path "C:\\cloudbaseinit_unattended"' failed too many times.
0
]
tags: -worker-0
