time: 2017-07-04 15:45:14.798059Z
tags: worker-0
test: tests.ScenarioNoError.test_any_exception_occurred
time: 2017-07-04 15:45:15.682613Z
failure: tests.ScenarioNoError.test_any_exception_occurred [ multipart
Content-Type: text/x-traceback;charset=utf8,language=python
traceback
2D48
Traceback (most recent call last):
  File "/root/workspace/cloudbase-init-ci/argus/scenarios/base.py", line 54, in delegator
    test_name)()
  File "/root/workspace/cloudbase-init-ci/argus/tests/cloud/smoke.py", line 279, in test_any_exception_occurred
    self.assertEqual('', instance_traceback)
  File "/usr/lib/python2.7/unittest/case.py", line 513, in assertEqual
    assertion_func(first, second, msg=msg)
  File "/usr/lib/python2.7/unittest/case.py", line 506, in _baseAssertEqual
    raise self.failureException(msg)
AssertionError: '' != u'C:\\Program Files\\Cloudbase \r\nSolutions\\Cloudbase-Init\\log\\cloudbase-init.log:43:2017-07-04 15:45:02.056 \r\n2096 DEBUG cloudbaseinit.utils.classloader [-] Loading class \r\n\'cloudbaseinit.plugins.windows.winrmlistener.ConfigWinRMListenerPlugin\' \r\nload_class C:\\Program Files\\Cloudbase Solutions\\Cloudbase-Init\\Python\\lib\\site-\r\npackages\\cloudbaseinit\\utils\\classloader.py:27\r\n  C:\\Program Files\\Cloudbase \r\nSolutions\\Cloudbase-Init\\log\\cloudbase-init.log:44:2017-07-04 15:45:02.056 \r\n2096 DEBUG cloudbaseinit.utils.classloader [-] Loading class \'cloudbaseinit.plu\r\ngins.windows.winrmcertificateauth.ConfigWinRMCertificateAuthPlugin\' load_class \r\nC:\\Program Files\\Cloudbase Solutions\\Cloudbase-Init\\Python\\lib\\site-packages\\cl\r\noudbaseinit\\utils\\classloader.py:27\r\n  C:\\Program Files\\Cloudbase \r\nSolutions\\Cloudbase-Init\\log\\cloudbase-init.log:45:2017-07-04 15:45:02.056 \r\n2096 DEBUG cloudbaseinit.utils.classloader [-] Loading class \r\n\'cloudbaseinit.plugins.common.localscripts.LocalScriptsPlugin\' load_class \r\nC:\\Program Files\\Cloudbase Solutions\\Cloudbase-Init\\Python\\lib\\site-packages\\cl\r\noudbaseinit\\utils\\classloader.py:27\r\n  C:\\Program Files\\Cloudbase \r\nSolutions\\Cloudbase-Init\\log\\cloudbase-init.log:46:2017-07-04 15:45:02.056 \r\n2096 INFO cloudbaseinit.init [-] Executing plugins for stage \r\n\'PRE_METADATA_DISCOVERY\':\r\n  C:\\Program Files\\Cloudbase \r\nSolutions\\Cloudbase-Init\\log\\cloudbase-init.log:47:2017-07-04 15:45:02.071 \r\n2096 INFO cloudbaseinit.init [-] Executing plugin \'MTUPlugin\'\r\n  C:\\Program Files\\Cloudbase \r\nSolutions\\Cloudbase-Init\\log\\cloudbase-init.log:48:2017-07-04 15:45:02.071 \r\n2096 DEBUG cloudbaseinit.utils.classloader [-] Loading class \r\n\'cloudbaseinit.osutils.windows.WindowsUtils\' load_class C:\\Program \r\nFiles\\Cloudbase Solutions\\Cloudbase-Init\\Python\\lib\\site-packages\\cloudbaseinit\r\n\\utils\\classloader.py:27\r\n  C:\\Program Files\\Cloudbase \r\nSolutions\\Cloudbase-Init\\log\\cloudbase-init.log:49:2017-07-04 15:45:02.087 \r\n2096 DEBUG cloudbaseinit.plugins.common.mtu [-] Could not obtain the MTU \r\nconfiguration via DHCP for interface "00:15:5D:01:15:00" execute C:\\Program \r\nFiles\\Cloudbase Solutions\\Cloudbase-Init\\Python\\lib\\site-packages\\cloudbaseinit\r\n\\plugins\\common\\mtu.py:46\r\n  C:\\Program Files\\Cloudbase \r\nSolutions\\Cloudbase-Init\\log\\cloudbase-init.log:50:2017-07-04 15:45:02.087 \r\n2096 DEBUG cloudbaseinit.utils.classloader [-] Loading class \r\n\'cloudbaseinit.metadata.services.\' load_class C:\\Program Files\\Cloudbase Soluti\r\nons\\Cloudbase-Init\\Python\\lib\\site-packages\\cloudbaseinit\\utils\\classloader.py:\r\n27\r\n  C:\\Program Files\\Cloudbase \r\nSolutions\\Cloudbase-Init\\log\\cloudbase-init.log:51:2017-07-04 15:45:02.087 \r\n2096 ERROR cloudbaseinit.metadata.factory [-] Failed to load metadata service \r\n\'cloudbaseinit.metadata.services.\'\r\n  C:\\Program Files\\Cloudbase \r\nSolutions\\Cloudbase-Init\\log\\cloudbase-init.log:52:2017-07-04 15:45:02.087 \r\n2096 ERROR cloudbaseinit.metadata.factory [-] \'module\' object has no attribute \r\n\'\'\r\n> C:\\Program Files\\Cloudbase \r\nSolutions\\Cloudbase-Init\\log\\cloudbase-init.log:53:2017-07-04 15:45:02.087 \r\n2096 ERROR cloudbaseinit.metadata.factory Traceback (most recent call last):\r\n  C:\\Program Files\\Cloudbase \r\nSolutions\\Cloudbase-Init\\log\\cloudbase-init.log:54:2017-07-04 15:45:02.087 \r\n2096 ERROR cloudbaseinit.metadata.factory   File "C:\\Program Files\\Cloudbase So\r\nlutions\\Cloudbase-Init\\Python\\lib\\site-packages\\cloudbaseinit\\metadata\\factory.\r\npy", line 33, in get_metadata_service\r\n  C:\\Program Files\\Cloudbase \r\nSolutions\\Cloudbase-Init\\log\\cloudbase-init.log:55:2017-07-04 15:45:02.087 \r\n2096 ERROR cloudbaseinit.metadata.factory     service = \r\ncl.load_class(class_path)()\r\n  C:\\Program Files\\Cloudbase \r\nSolutions\\Cloudbase-Init\\log\\cloudbase-init.log:56:2017-07-04 15:45:02.087 \r\n2096 ERROR cloudbaseinit.metadata.factory   File "C:\\Program Files\\Cloudbase So\r\nlutions\\Cloudbase-Init\\Python\\lib\\site-packages\\cloudbaseinit\\utils\\classloader\r\n.py", line 30, in load_class\r\n  C:\\Program Files\\Cloudbase \r\nSolutions\\Cloudbase-Init\\log\\cloudbase-init.log:57:2017-07-04 15:45:02.087 \r\n2096 ERROR cloudbaseinit.metadata.factory     return getattr(module, parts[1])\r\n  C:\\Program Files\\Cloudbase \r\nSolutions\\Cloudbase-Init\\log\\cloudbase-init.log:58:2017-07-04 15:45:02.087 \r\n2096 ERROR cloudbaseinit.metadata.factory AttributeError: \'module\' object has \r\nno attribute \'\'\r\n  C:\\Program Files\\Cloudbase \r\nSolutions\\Cloudbase-Init\\log\\cloudbase-init.log:59:2017-07-04 15:45:02.087 \r\n2096 ERROR cloudbaseinit.metadata.factory \r\n  C:\\Program Files\\Cloudbase \r\nSolutions\\Cloudbase-Init\\log\\cloudbase-init.log:60:2017-07-04 15:45:02.103 \r\n2096 ERROR cloudbaseinit.init [-] No metadata service found\r\n  C:\\Program Files\\Cloudbase \r\nSolutions\\Cloudbase-Init\\log\\cloudbase-init.log:61:2017-07-04 15:45:02.103 \r\n2096 INFO cloudbaseinit.init [-] Plugins execution done\r\n  C:\\Program Files\\Cloudbase \r\nSolutions\\Cloudbase-Init\\log\\cloudbase-init.log:62:2017-07-04 15:45:02.103 \r\n2096 INFO cloudbaseinit.init [-] Stopping Cloudbase-Init service\r\n  C:\\Program Files\\Cloudbase \r\nSolutions\\Cloudbase-Init\\log\\cloudbase-init.log:63:2017-07-04 15:45:05.108 \r\n2096 DEBUG cloudbaseinit.osutils.windows [-] Stopping service cloudbase-init \r\nstop_service C:\\Program Files\\Cloudbase Solutions\\Cloudbase-Init\\Python\\lib\\sit\r\ne-packages\\cloudbaseinit\\osutils\\windows.py:943\r\n  C:\\Program Files\\Cloudbase \r\nSolutions\\Cloudbase-Init\\log\\cloudbase-init-unattend.log:12:2017-07-04 \r\n15:44:36.020 1756 DEBUG cloudbaseinit.utils.classloader [-] Loading class \r\n\'cloudbaseinit.plugins.common.mtu.MTUPlugin\' load_class C:\\Program \r\nFiles\\Cloudbase Solutions\\Cloudbase-Init\\Python\\lib\\site-packages\\cloudbaseinit\r\n\\utils\\classloader.py:27\r\n  C:\\Program Files\\Cloudbase \r\nSolutions\\Cloudbase-Init\\log\\cloudbase-init-unattend.log:13:2017-07-04 \r\n15:44:36.020 1756 DEBUG cloudbaseinit.utils.classloader [-] Loading class \r\n\'cloudbaseinit.plugins.windows.extendvolumes.ExtendVolumesPlugin\' load_class \r\nC:\\Program Files\\Cloudbase Solutions\\Cloudbase-Init\\Python\\lib\\site-packages\\cl\r\noudbaseinit\\utils\\classloader.py:27\r\n  C:\\Program Files\\Cloudbase \r\nSolutions\\Cloudbase-Init\\log\\cloudbase-init-unattend.log:14:2017-07-04 \r\n15:44:36.020 1756 DEBUG cloudbaseinit.utils.classloader [-] Loading class \r\n\'cloudbaseinit.plugins.common.sethostname.SetHostNamePlugin\' load_class \r\nC:\\Program Files\\Cloudbase Solutions\\Cloudbase-Init\\Python\\lib\\site-packages\\cl\r\noudbaseinit\\utils\\classloader.py:27\r\n  C:\\Program Files\\Cloudbase \r\nSolutions\\Cloudbase-Init\\log\\cloudbase-init-unattend.log:15:2017-07-04 \r\n15:44:36.035 1756 INFO cloudbaseinit.init [-] Executing plugins for stage \r\n\'PRE_METADATA_DISCOVERY\':\r\n  C:\\Program Files\\Cloudbase \r\nSolutions\\Cloudbase-Init\\log\\cloudbase-init-unattend.log:16:2017-07-04 \r\n15:44:36.035 1756 INFO cloudbaseinit.init [-] Executing plugin \'MTUPlugin\'\r\n  C:\\Program Files\\Cloudbase \r\nSolutions\\Cloudbase-Init\\log\\cloudbase-init-unattend.log:17:2017-07-04 \r\n15:44:36.035 1756 DEBUG cloudbaseinit.utils.classloader [-] Loading class \r\n\'cloudbaseinit.osutils.windows.WindowsUtils\' load_class C:\\Program \r\nFiles\\Cloudbase Solutions\\Cloudbase-Init\\Python\\lib\\site-packages\\cloudbaseinit\r\n\\utils\\classloader.py:27\r\n  C:\\Program Files\\Cloudbase \r\nSolutions\\Cloudbase-Init\\log\\cloudbase-init-unattend.log:18:2017-07-04 \r\n15:44:36.035 1756 DEBUG cloudbaseinit.plugins.common.mtu [-] Could not obtain \r\nthe MTU configuration via DHCP for interface "00:15:5D:01:15:00" execute \r\nC:\\Program Files\\Cloudbase Solutions\\Cloudbase-Init\\Python\\lib\\site-packages\\cl\r\noudbaseinit\\plugins\\common\\mtu.py:46\r\n  C:\\Program Files\\Cloudbase \r\nSolutions\\Cloudbase-Init\\log\\cloudbase-init-unattend.log:19:2017-07-04 \r\n15:44:36.035 1756 DEBUG cloudbaseinit.utils.classloader [-] Loading class \r\n\'cloudbaseinit.metadata.services.\' load_class C:\\Program Files\\Cloudbase Soluti\r\nons\\Cloudbase-Init\\Python\\lib\\site-packages\\cloudbaseinit\\utils\\classloader.py:\r\n27\r\n  C:\\Program Files\\Cloudbase \r\nSolutions\\Cloudbase-Init\\log\\cloudbase-init-unattend.log:20:2017-07-04 \r\n15:44:36.051 1756 ERROR cloudbaseinit.metadata.factory [-] Failed to load \r\nmetadata service \'cloudbaseinit.metadata.services.\'\r\n  C:\\Program Files\\Cloudbase \r\nSolutions\\Cloudbase-Init\\log\\cloudbase-init-unattend.log:21:2017-07-04 \r\n15:44:36.051 1756 ERROR cloudbaseinit.metadata.factory [-] \'module\' object has \r\nno attribute \'\'\r\n> C:\\Program Files\\Cloudbase \r\nSolutions\\Cloudbase-Init\\log\\cloudbase-init-unattend.log:22:2017-07-04 \r\n15:44:36.051 1756 ERROR cloudbaseinit.metadata.factory Traceback (most recent \r\ncall last):\r\n  C:\\Program Files\\Cloudbase \r\nSolutions\\Cloudbase-Init\\log\\cloudbase-init-unattend.log:23:2017-07-04 \r\n15:44:36.051 1756 ERROR cloudbaseinit.metadata.factory   File "C:\\Program \r\nFiles\\Cloudbase Solutions\\Cloudbase-Init\\Python\\lib\\site-packages\\cloudbaseinit\r\n\\metadata\\factory.py", line 33, in get_metadata_service\r\n  C:\\Program Files\\Cloudbase \r\nSolutions\\Cloudbase-Init\\log\\cloudbase-init-unattend.log:24:2017-07-04 \r\n15:44:36.051 1756 ERROR cloudbaseinit.metadata.factory     service = \r\ncl.load_class(class_path)()\r\n  C:\\Program Files\\Cloudbase \r\nSolutions\\Cloudbase-Init\\log\\cloudbase-init-unattend.log:25:2017-07-04 \r\n15:44:36.051 1756 ERROR cloudbaseinit.metadata.factory   File "C:\\Program \r\nFiles\\Cloudbase Solutions\\Cloudbase-Init\\Python\\lib\\site-packages\\cloudbaseinit\r\n\\utils\\classloader.py", line 30, in load_class\r\n  C:\\Program Files\\Cloudbase \r\nSolutions\\Cloudbase-Init\\log\\cloudbase-init-unattend.log:26:2017-07-04 \r\n15:44:36.051 1756 ERROR cloudbaseinit.metadata.factory     return \r\ngetattr(module, parts[1])\r\n  C:\\Program Files\\Cloudbase \r\nSolutions\\Cloudbase-Init\\log\\cloudbase-init-unattend.log:27:2017-07-04 \r\n15:44:36.051 1756 ERROR cloudbaseinit.metadata.factory AttributeError: \r\n\'module\' object has no attribute \'\'\r\n  C:\\Program Files\\Cloudbase \r\nSolutions\\Cloudbase-Init\\log\\cloudbase-init-unattend.log:28:2017-07-04 \r\n15:44:36.051 1756 ERROR cloudbaseinit.metadata.factory \r\n  C:\\Program Files\\Cloudbase \r\nSolutions\\Cloudbase-Init\\log\\cloudbase-init-unattend.log:29:2017-07-04 \r\n15:44:36.051 1756 ERROR cloudbaseinit.init [-] No metadata service found\r\n  C:\\Program Files\\Cloudbase \r\nSolutions\\Cloudbase-Init\\log\\cloudbase-init-unattend.log:30:2017-07-04 \r\n15:44:36.051 1756 INFO cloudbaseinit.init [-] Plugins execution done'
0
]
tags: -worker-0
