time: 2017-07-05 12:40:46.604315Z
tags: worker-0
test: setUpClass (tests.ScenarioNoError)
time: 2017-07-05 12:40:46.604315Z
failure: setUpClass (tests.ScenarioNoError) [ multipart
Content-Type: text/x-traceback;charset=utf8,language=python
traceback
43F
Traceback (most recent call last):
  File "/root/workspace/cloudbase-init-ci/argus/scenarios/base.py", line 144, in setUpClass
    cls.prepare_instance()
  File "/root/workspace/cloudbase-init-ci/argus/scenarios/base.py", line 162, in prepare_instance
    cls.prepare_recipe()
  File "/root/workspace/cloudbase-init-ci/argus/scenarios/cloud/base.py", line 31, in prepare_recipe
    return cls.recipe.prepare(service_type=cls.service_type)
  File "/root/workspace/cloudbase-init-ci/argus/recipes/cloud/base.py", line 184, in prepare
    self.wait_for_boot_completion()
  File "/root/workspace/cloudbase-init-ci/argus/recipes/cloud/windows.py", line 51, in wait_for_boot_completion
    self._backend.remote_client.manager.wait_boot_completion()
  File "/root/workspace/cloudbase-init-ci/argus/util.py", line 267, in __get__
    instance.__dict__[self.name] = result = self.func(instance)
  File "/root/workspace/cloudbase-init-ci/argus/backends/local/local_backend.py", line 27, in get_remote_client
    protocol, kwargs)
TypeError: get_remote_client() takes at most 4 arguments (5 given)
0
]
tags: -worker-0
